[2023-06-16T22:08:54.942+0000] {taskinstance.py:1103} INFO - Dependencies all met for dep_context=non-requeueable deps ti=<TaskInstance: demo_dag.executor_task scheduled__2023-06-16T21:00:00+00:00 [queued]>
[2023-06-16T22:08:54.954+0000] {taskinstance.py:1103} INFO - Dependencies all met for dep_context=requeueable deps ti=<TaskInstance: demo_dag.executor_task scheduled__2023-06-16T21:00:00+00:00 [queued]>
[2023-06-16T22:08:54.955+0000] {taskinstance.py:1308} INFO - Starting attempt 1 of 4
[2023-06-16T22:08:55.037+0000] {taskinstance.py:1327} INFO - Executing <Task(BashOperator): executor_task> on 2023-06-16 21:00:00+00:00
[2023-06-16T22:08:55.045+0000] {standard_task_runner.py:57} INFO - Started process 68 to run task
[2023-06-16T22:08:55.049+0000] {standard_task_runner.py:84} INFO - Running: ['***', 'tasks', 'run', 'demo_dag', 'executor_task', 'scheduled__2023-06-16T21:00:00+00:00', '--job-id', '109', '--raw', '--subdir', 'DAGS_FOLDER/demo_dag.py', '--cfg-path', '/tmp/tmplb5gkfco']
[2023-06-16T22:08:55.051+0000] {standard_task_runner.py:85} INFO - Job 109: Subtask executor_task
[2023-06-16T22:08:55.233+0000] {task_command.py:410} INFO - Running <TaskInstance: demo_dag.executor_task scheduled__2023-06-16T21:00:00+00:00 [running]> on host 31a6f4abb1ec
[2023-06-16T22:08:55.671+0000] {warnings.py:110} WARNING - /home/***/.local/lib/python3.7/site-packages/***/utils/context.py:205: AirflowContextDeprecationWarning: Accessing 'execution_date' from the template is deprecated and will be removed in a future version. Please use 'data_interval_start' or 'logical_date' instead.
  warnings.warn(_create_deprecation_warning(key, self._deprecation_replacements[key]))

[2023-06-16T22:08:55.977+0000] {taskinstance.py:1547} INFO - Exporting env vars: AIRFLOW_CTX_DAG_EMAIL='personaltraingcp@gmail.com' AIRFLOW_CTX_DAG_OWNER='Leyner_Bejarano' AIRFLOW_CTX_DAG_ID='demo_dag' AIRFLOW_CTX_TASK_ID='executor_task' AIRFLOW_CTX_EXECUTION_DATE='2023-06-16T21:00:00+00:00' AIRFLOW_CTX_TRY_NUMBER='1' AIRFLOW_CTX_DAG_RUN_ID='scheduled__2023-06-16T21:00:00+00:00'
[2023-06-16T22:08:55.979+0000] {subprocess.py:63} INFO - Tmp dir root location: 
 /tmp
[2023-06-16T22:08:55.979+0000] {subprocess.py:75} INFO - Running command: ['/bin/bash', '-c', ' \n        cd /opt/***/dags/scripts &&\n        pip install -r requirements.txt &&\n        python lambdaExecutor.py -dt 2023-06-16 -dh 21 -q https://sqs.us-east-2.amazonaws.com/147929168898/lokaInterviewSQS -ak AKIASE4KD7QBGVHE4G7U -sk *** &&\n        pip freeze\n        ']
[2023-06-16T22:08:55.993+0000] {subprocess.py:86} INFO - Output:
[2023-06-16T22:09:03.361+0000] {subprocess.py:93} INFO - Defaulting to user installation because normal site-packages is not writeable
[2023-06-16T22:09:05.985+0000] {subprocess.py:93} INFO - Collecting boto3==1.26.151 (from -r requirements.txt (line 1))
[2023-06-16T22:09:06.122+0000] {subprocess.py:93} INFO -   Downloading boto3-1.26.151-py3-none-any.whl (135 kB)
[2023-06-16T22:09:06.415+0000] {subprocess.py:93} INFO -      ━━━━━━━━━━━━━━━━━━━━━━━━━━━━━━━━━━━━━ 135.6/135.6 kB 440.7 kB/s eta 0:00:00
[2023-06-16T22:09:08.306+0000] {subprocess.py:93} INFO - Collecting botocore<1.30.0,>=1.29.151 (from boto3==1.26.151->-r requirements.txt (line 1))
[2023-06-16T22:09:08.337+0000] {subprocess.py:93} INFO -   Downloading botocore-1.29.155-py3-none-any.whl (10.9 MB)
[2023-06-16T22:09:12.150+0000] {subprocess.py:93} INFO -      ━━━━━━━━━━━━━━━━━━━━━━━━━━━━━━━━━━━━━━━━ 10.9/10.9 MB 2.9 MB/s eta 0:00:00
[2023-06-16T22:09:12.227+0000] {subprocess.py:93} INFO - Requirement already satisfied: jmespath<2.0.0,>=0.7.1 in /home/***/.local/lib/python3.7/site-packages (from boto3==1.26.151->-r requirements.txt (line 1)) (0.10.0)
[2023-06-16T22:09:12.228+0000] {subprocess.py:93} INFO - Requirement already satisfied: s3transfer<0.7.0,>=0.6.0 in /home/***/.local/lib/python3.7/site-packages (from boto3==1.26.151->-r requirements.txt (line 1)) (0.6.1)
[2023-06-16T22:09:12.241+0000] {subprocess.py:93} INFO - Requirement already satisfied: python-dateutil<3.0.0,>=2.1 in /home/***/.local/lib/python3.7/site-packages (from botocore<1.30.0,>=1.29.151->boto3==1.26.151->-r requirements.txt (line 1)) (2.8.2)
[2023-06-16T22:09:12.243+0000] {subprocess.py:93} INFO - Requirement already satisfied: urllib3<1.27,>=1.25.4 in /home/***/.local/lib/python3.7/site-packages (from botocore<1.30.0,>=1.29.151->boto3==1.26.151->-r requirements.txt (line 1)) (1.26.15)
[2023-06-16T22:09:12.941+0000] {subprocess.py:93} INFO - Requirement already satisfied: six>=1.5 in /home/***/.local/lib/python3.7/site-packages (from python-dateutil<3.0.0,>=2.1->botocore<1.30.0,>=1.29.151->boto3==1.26.151->-r requirements.txt (line 1)) (1.16.0)
[2023-06-16T22:09:31.317+0000] {subprocess.py:93} INFO - Installing collected packages: botocore, boto3
[2023-06-16T22:09:31.318+0000] {subprocess.py:93} INFO -   Attempting uninstall: botocore
[2023-06-16T22:09:31.320+0000] {subprocess.py:93} INFO -     Found existing installation: botocore 1.29.76
[2023-06-16T22:09:32.222+0000] {subprocess.py:93} INFO -     Uninstalling botocore-1.29.76:
[2023-06-16T22:09:32.279+0000] {subprocess.py:93} INFO - ERROR: Could not install packages due to an OSError: [('/home/***/.local/lib/python3.7/site-packages/botocore-1.29.76.dist-info/WHEEL', '/home/***/.local/lib/python3.7/site-packages/~-tocore-1.29.76.dist-info/WHEEL', "[Errno 2] No such file or directory: '/home/***/.local/lib/python3.7/site-packages/botocore-1.29.76.dist-info/WHEEL'"), ('/home/***/.local/lib/python3.7/site-packages/botocore-1.29.76.dist-info/INSTALLER', '/home/***/.local/lib/python3.7/site-packages/~-tocore-1.29.76.dist-info/INSTALLER', "[Errno 2] No such file or directory: '/home/***/.local/lib/python3.7/site-packages/botocore-1.29.76.dist-info/INSTALLER'"), ('/home/***/.local/lib/python3.7/site-packages/botocore-1.29.76.dist-info/', '/home/***/.local/lib/python3.7/site-packages/~-tocore-1.29.76.dist-info', "[Errno 2] No such file or directory: '/home/***/.local/lib/python3.7/site-packages/botocore-1.29.76.dist-info/'")]
[2023-06-16T22:09:32.279+0000] {subprocess.py:93} INFO - 
[2023-06-16T22:09:33.277+0000] {subprocess.py:97} INFO - Command exited with return code 1
[2023-06-16T22:09:33.294+0000] {taskinstance.py:1824} ERROR - Task failed with exception
Traceback (most recent call last):
  File "/home/airflow/.local/lib/python3.7/site-packages/airflow/operators/bash.py", line 211, in execute
    f"Bash command failed. The command returned a non-zero exit code {result.exit_code}."
airflow.exceptions.AirflowException: Bash command failed. The command returned a non-zero exit code 1.
[2023-06-16T22:09:33.300+0000] {taskinstance.py:1350} INFO - Marking task as UP_FOR_RETRY. dag_id=demo_dag, task_id=executor_task, execution_date=20230616T210000, start_date=20230616T220854, end_date=20230616T220933
[2023-06-16T22:09:33.697+0000] {standard_task_runner.py:109} ERROR - Failed to execute job 109 for task executor_task (Bash command failed. The command returned a non-zero exit code 1.; 68)
[2023-06-16T22:09:33.729+0000] {local_task_job_runner.py:225} INFO - Task exited with return code 1
[2023-06-16T22:09:33.768+0000] {taskinstance.py:2651} INFO - 0 downstream tasks scheduled from follow-on schedule check
